Workbook

Sheet GESAMT
A1: Nutzungszeiten FFK 2025 | B1: Kirche und Nebenräume | H1: Casalis | J1: Entrée
A2: Nutzer | B2: Gottesdienste, Kirchenmusik Veranstalt. | C2: Anteil % ohne BO | D2: Orgelübzeiten (Umlage anteilig, alle) | E2: Offene Kirche (Umlage anteilig, alle) | F2: Summe inkl. off. Kirche + Orgelübz. | G2: Anteil inkl. off. Kirche + Orgelübz. | H2: Gottes-dienste VAs | I2: Anteil % | J2: Dauer | K2: Anteil %
A3: Franz. Kirche | B3: ='Franz. Kirche '!H72 -> 507.5 | C3: =B3/$B$8 -> 0.72785945 | D3: =C3*D7 -> 366.1133 | E3: =C3*E7 -> 64.415561 | F3: =B3+D3+E3 -> 938.02886 | G3: =F3/F7 -> 0.51363661 | H3: ='Franz. Kirche '!I72 -> 178 | I3: =H3/$H$7 -> 0.27932523 | J3: ='Franz. Kirche '!J72 -> 0 | K3: =J3/$J$7 -> 0
A4: EKD | B4: =EKD!G11 -> 36.5 | C4: =B4/$B$8 -> 0.052348512 | D4: =C4*D7 -> 26.331302 | E4: =C4*E7 -> 4.6328433 | F4: =B4+D4+E4 -> 67.464145 | G4: =F4/F7 -> 0.036941352 | H4: =EKD!H11 -> 32.5 | I4: =H4/$H$7 -> 0.051000392 | J4: =EKD!I11 -> 32.5 | K4: =J4/$J$7 -> 0.078078078
A5: Ev. Akademie | B5: =EAzB!G23 -> 153.25 | C5: =B5/$B$8 -> 0.21979204 | D5: =C5*D7 -> 110.5554 | E5: =C5*E7 -> 19.451596 | F5: =B5+D5+E5 -> 283.25699 | G5: =F5/F7 -> 0.15510308 | H5: =EAzB!H23 -> 129.25 | I5: =H5/$H$7 -> 0.20282464 | J5: =EAzB!I23 -> 129.25 | K5: =J5/$J$7 -> 0.31051051
A6: Besondere Orte | B6: ='Besondere Orte'!H89 -> 537.5 | F6: =B6+D6+E6 -> 537.5 | G6: =F6/F7 -> 0.29431896 | H6: ='Besondere Orte'!I89 -> 297.5 | I6: =H6/$H$7 -> 0.46684974 | J6: ='Besondere Orte'!J89 -> 254.5 | K6: =J6/$J$7 -> 0.61141141
A7: Summe | B7: =SUM(B3:B6) -> 1234.75 | C7: =SUM(C3:C6) -> 1 | D7: =Orgelprobe!H51+Orgelprobe!H51 -> 503 | E7: ='Offene Kirche'!I24 -> 88.5 | F7: =SUM(F3:F6) -> 1826.25 | G7: =SUM(G3:G6) -> 1 | H7: =SUM(H3:H6) -> 637.25 | I7: =SUM(I3:I6) -> 1 | J7: =SUM(J3:J6) -> 416.25 | K7: =SUM(K3:K6) -> 1
A8: Summe ohne BO | B8: =B7-B6 -> 697.25

Sheet Besondere Orte
A1: Veranstalter | B1: VA | C1: Datum | D1: Startzeit | E1: Endzeit | F1: Differenz | G1: Umrech-nung | H1: Kirchsaal | I1: Georges-Casalis-Saal | J1: Entrée
A2: Weltkonzerte | B2: Konzert | C2: 44927 | D2: 0.54166667 | E2: 0.95833333 | F2: =E2-D2 -> 0.41666667 | G2: 10 | H2: =G2 -> 10
A3: Vero | B3: Konzert | C3: 44933 | D3: 0.58333333 | E3: 0.83333333 | F3: =E3-D3 -> 0.25 | G3: 6 | H3: 6 | I3: 6 | J3: 6
A4: Orchester Ronny Heinrich | B4: Konzert | C4: 44934 | D4: 0.5625 | E4: 0.8125 | F4: =E4-D4 -> 0.25 | G4: 6 | H4: =G4 -> 6
A5: FRANZHANS 06 Ltd. Agentur für Kultur | B5: Konzert | C5: 44939 | D5: 0.66666667 | E5: 0.91666667 | F5: =E5-D5 -> 0.25 | G5: 6 | H5: =G5 -> 6
A6: FRANZHANS 06 Ltd. Agentur für Kultur | B6: Konzert | C6: 44940 | D6: 0.66666667 | E6: 0.91666667 | F6: =E6-D6 -> 0.25 | G6: 6 | H6: =G6 -> 6
A7: BRANDS ALIVE | B7: Dinner | C7: 44943 | D7: 0.29166667 | E7: 0.79166667 | F7: =E7-D7 -> 0.5 | G7: 12 | H7: =G7 -> 12 | I7: =G7 -> 12 | J7: =G7 -> 12
A8: BRANDS ALIVE | B8: Dinner | C8: 44944 | D8: 0.375 | E8: 0.041666667 | F8: 0.66666667 | G8: 16 | H8: =G8 -> 16 | I8: =G8 -> 16 | J8: =G8 -> 16
A9: BRANDS ALIVE | B9: Dinner | C9: 44945 | D9: 0.29166667 | E9: 0.5 | F9: =E9-D9 -> 0.20833333 | G9: 5 | H9: =G9 -> 5 | I9: =G9 -> 5 | J9: =G9 -> 5
A10: FRANZHANS 06 Ltd. Agentur für Kultur | B10: Konzert | C10: 44946 | D10: 0.66666667 | E10: 0.91666667 | F10: =E10-D10 -> 0.25 | G10: 6 | H10: =G10 -> 6
A11: FRANZHANS 06 Ltd. Agentur für Kultur | B11: Konzert | C11: 44947 | D11: 0.66666667 | E11: 0.91666667 | F11: =E11-D11 -> 0.25 | G11: 6 | H11: =G11 -> 6
A12: KaMü GmbH | B12: Konzert | C12: 44955 | D12: 0.60416667 | E12: 0.8125 | F12: =E12-D12 -> 0.20833333 | G12: 5 | H12: =G12 -> 5
A13: insolite Germany GmbH | B13: Abendveranstaltung | C13: 44981 | D13: 0.6875 | E13: 0.9375 | F13: =E13-D13 -> 0.25 | G13: 6 | H13: =G13 -> 6 | J13: =G13 -> 6
A14: Berlin Klassik Artist & Culture Management | B14: Konzert | C14: 45000 | D14: 0.66666667 | E14: 0.91666667 | F14: =E14-D14 -> 0.25 | G14: 6 | H14: =G14 -> 6 | J14: =G14 -> 6
A15: Becker Büttner | B15: Energiekonfrenz | C15: 45014 | D15: 0.33333333 | E15: 0.6875 | F15: =E15-D15 -> 0.35416667 | G15: 8.5 | H15: =G15 -> 8.5 | I15: =G15 -> 8.5 | J15: =G15 -> 8.5
A16: Deutsches Verpackungsinstitut | B16: Abendveranstaltung | C16: 45015 | D16: 0.72916667 | E16: 1 | F16: =E16-D16 -> 0.27083333 | G16: 6.5 | I16: =G16 -> 6.5 | J16: =G16 -> 6.5
A17: BESONDERE ORTE | B17: Tour | C17: 45034 | D17: 0.33333333 | E17: 0.54166667 | F17: =E17-D17 -> 0.20833333 | G17: 5 | H17: =G17 -> 5 | I17: =G17 -> 5
A18: BESONDERE ORTE | B18: Poetry Slam | C18: 45034 | D18: 0.75 | E18: 0.91666667 | F18: =E18-D18 -> 0.16666667 | G18: 4 | I18: =G18 -> 4
A19: Astor Montero Enterprises | B19: Incentive-Reise DAIKIN | C19: 45035 | D19: 0.33333333 | E19: 0.84375 | F19: =E19-D19 -> 0.51041667 | G19: 12.25 | H19: =G19 -> 12.25
A20: Konrad-Adenauer-Stiftung e.V. | B20: Tagung | C20: 45043 | D20: 0.5 | E20: 0.95833333 | F20: =E20-D20 -> 0.45833333 | G20: 11 | H20: =G20 -> 11 | I20: =G20 -> 11 | J20: =G20 -> 11
A21: Hans-Böckler-Stiftung | B21: IMK-Forum 2023 | C21: 45050 | D21: 0.375 | E21: 0.95833333 | F21: =E21-D21 -> 0.58333333 | G21: 14 | H21: =G21 -> 14 | I21: =G21 -> 14 | J21: =G21 -> 14
A22: Tina Tandler | B22: Konzert | C22: 45052 | D22: 0.5625 | E22: 0.96875 | F22: =E22-D22 -> 0.40625 | G22: 9.75 | H22: =G22 -> 9.75
A23: Pommersche Genossenschaft des Johanniter Ordens | B23: Get-together | C23: 45053 | D23: 0.41666667 | E23: 0.54166667 | F23: =E23-D23 -> 0.125 | G23: 3 | H23: =G23 -> 3 | K23: Gehört zu uns oder Kirche?
A24: KaMü GmbH | B24: Konzert | C24: 45053 | D24: 0.60416667 | E24: 0.8125 | F24: =E24-D24 -> 0.20833333 | G24: 5 | H24: =G24 -> 5
A25: Friedrich-Ebert-Stiftung | B25: Preisverleihung | C25: 45056 | D25: 0.52083333 | E25: 0.875 | F25: =E25-D25 -> 0.35416667 | G25: 8.5 | H25: =G25 -> 8.5 | I25: =G25 -> 8.5 | J25: =G25 -> 8.5
A26: AG Familienrecht im DAV c/o conventionPARTNERS | B26: Forum | C26: 45058 | D26: 0.33333333 | E26: 0.75 | F26: =E26-D26 -> 0.41666667 | G26: 10 | H26: =G26 -> 10 | I26: =G26 -> 10 | J26: =G26 -> 10
A27: Orchester Ronny Heinrich | B27: Muttertagskonzert | C27: 45060 | D27: 0.5625 | E27: 0.8125 | F27: =E27-D27 -> 0.25 | G27: 6 | H27: 6
A28: BO | B28: Fotoshooting | C28: 45062 | D28: 0.54166667 | E28: 0.75 | F28: =E28-D28 -> 0.20833333 | G28: 5 | I28: =G28 -> 5
A29: Weltkonzerte | B29: Konzert | C29: 45066 | D29: 0.6875 | E29: 0.9375 | F29: =E29-D29 -> 0.25 | G29: 6 | H29: =G29 -> 6
A30: Friedrich-Naumann-Stiftung für die Freiheit | B30: Konzert | C30: 45073 | D30: 0.5 | E30: 0.91666667 | F30: =E30-D30 -> 0.41666667 | G30: 10 | H30: =G30 -> 10
A31: Weltkonzerte | B31: Konzert | C31: 45074 | D31: 0.5625 | E31: 0.8125 | F31: =E31-D31 -> 0.25 | G31: 6 | H31: =G31 -> 6
A32: RIAS Berlin Commission | B32: Medienpreisverleihung | C32: 45078 | D32: 0.625 | E32: 0.96875 | F32: =E32-D32 -> 0.34375 | G32: 8.25 | H32: =G32 -> 8.25
A33: Friedrich-Naumann-Stiftung für die Freiheit | B33: 70 Jahre Volksaufstand vom 17. Juni 1953 | C33: 45092 | D33: 0.63541667 | E33: 0.85416667 | F33: =E33-D33 -> 0.21875 | G33: 5.25 | I33: =G33 -> 5.25 | J33: =G33 -> 5.25
A34: Collegium Musicum Berlin | B34: Sinfoniekonzert | C34: 45107 | D34: 0.66666667 | E34: 0.91666667 | F34: =E34-D34 -> 0.25 | G34: 6 | H34: =G34 -> 6 | I34: =H34 -> 6
A35: Begehung BKA (Nationalstiftung) | C35: 45092 | D35: 0.45833333 | E35: 0.5 | F35: =E35-D35 -> 0.041666667 | G35: 1 | H35: =G35 -> 1 | I35: =G35 -> 1 | J35: =H35 -> 1
A36: Deutsche Nationalstiftung | B36: Verleihung Deutscher Nationalpreis | C36: 45112 | D36: 0.57291667 | E36: 0.6875 | F36: =E36-D36 -> 0.11458333 | G36: 2.75 | H36: =G36 -> 2.75
A37: BO | B37: Dienstleistertreffen Hochzeitsbranche | C37: 45112 | D37: 0.79166667 | E37: 0.91666667 | F37: =E37-D37 -> 0.125 | G37: 3 | H37: =G37 -> 3 | I37: =H37 -> 3 | J37: =I37 -> 3
A38: Deutsche Nationalstiftung | B38: Verleihung Deutscher Nationalpreis | C38: 45113 | D38: 0.3125 | E38: 0.60416667 | F38: =E38-D38 -> 0.29166667 | G38: 7 | H38: =G38 -> 7 | I38: =H38 -> 7 | J38: =I38 -> 7
A39: Landesvertretung Saarland | B39: Deutsch-Französisches Freundschaftskonzert | C39: 45114 | D39: 0.625 | E39: 0.95833333 | F39: =E39-D39 -> 0.33333333 | G39: 8 | H39: =G39 -> 8 | I39: =H39 -> 8 | J39: =I39 -> 8
A40: KaMü GmbH | B40: Sommerkonzert | C40: 45115 | D40: 0.60416667 | E40: 0.8125 | F40: =E40-D40 -> 0.20833333 | G40: 5 | H40: =G40 -> 5
...

Sheet EAzB
A1: EAzB VA | B1: Datum Start | C1: Startzeit | D1: Endzeit | E1: Differenz | F1: Umrech-nung | G1: Kirchsaal | H1: Georges-Casalis-Saal | I1: Entrée
A2: Gottesdienst | B2: 44953 | C2: 0.70833333 | D2: 0.83333333 | E2: =D2-C2 -> 0.125 | F2: 3 | G2: =F2 -> 3
A3: Fachtagung | B3: 44987 | C3: 0.39583333 | D3: 0.91666667 | E3: =D3-C3 -> 0.52083333 | F3: 12.5 | G3: =F3 -> 12.5
A4: Fachtagung | B4: 44988 | C4: 0.33333333 | D4: 0.6875 | E4: =D4-C4 -> 0.35416667 | F4: 8.5 | G4: =F4 -> 8.5 | H4: =F4 -> 8.5 | I4: =F4 -> 8.5
A5: Fachtagung | B5: 44993 | C5: 0.29166667 | D5: 0.66666667 | E5: =D5-C5 -> 0.375 | F5: 9 | G5: =F5 -> 9 | H5: =F5 -> 9 | I5: =F5 -> 9
A6: Friedensgutachten | B6: 45091 | C6: 0.70833333 | D6: 0.875 | E6: =D6-C6 -> 0.16666667 | F6: 4 | G6: =F6 -> 4
A7: Flüchtlingssymposium | B7: 45103 | C7: 0.3125 | D7: 0.95833333 | E7: =D7-C7 -> 0.64583333 | F7: 15.5 | G7: =F7 -> 15.5 | H7: =G7 -> 15.5 | I7: =H7 -> 15.5
A8: Flüchtlingssymposium | B8: 45104 | C8: 0.3125 | D8: 0.60416667 | E8: =D8-C8 -> 0.29166667 | F8: 7 | G8: =F8 -> 7 | H8: =G8 -> 7 | I8: =H8 -> 7
A9: 2. Ortskräftekongress | B9: 45150 | C9: 0.3125 | D9: 0.77083333 | E9: =D9-C9 -> 0.45833333 | F9: 11 | G9: =F9 -> 11 | H9: =G9 -> 11 | I9: =H9 -> 11
A10: Internationales Friedenstreffen | B10: 45177 | C10: 0.41666667 | D10: 0.83333333 | E10: =D10-C10 -> 0.41666667 | F10: 10 | G10: =F10 -> 10 | H10: =G10 -> 10 | I10: =H10 -> 10
A11: Internationales Friedenstreffen | B11: 45178 | C11: 0.33333333 | D11: 0.625 | E11: =D11-C11 -> 0.29166667 | F11: 7 | G11: =F11 -> 7 | H11: =G11 -> 7 | I11: =H11 -> 7
A12: Internationales Friedenstreffen | B12: 45180 | C12: 0.33333333 | D12: 0.79166667 | E12: =D12-C12 -> 0.45833333 | F12: 11 | G12: =F12 -> 11 | H12: =G12 -> 11 | I12: =H12 -> 11
A13: Internationales Friedenstreffen | B13: 45181 | C13: 0.33333333 | D13: 0.60416667 | E13: =D13-C13 -> 0.27083333 | F13: 6.5 | G13: =F13 -> 6.5 | H13: =G13 -> 6.5 | I13: =H13 -> 6.5
A14: Pluriversum | B14: 45213 | C14: 0.75 | D14: 0.91666667 | E14: =D14-C14 -> 0.16666667 | F14: 4 | G14: =F14 -> 4
A15: Syrienkonferenz | B15: 45219 | C15: 0.32291667 | D15: 0.83333333 | E15: =D15-C15 -> 0.51041667 | F15: 12.25 | G15: =F15 -> 12.25 | H15: =G15 -> 12.25 | I15: =H15 -> 12.25
A16: Syrienkonferenz | B16: 45220 | C16: 0.33333333 | D16: 0.6875 | E16: =D16-C16 -> 0.35416667 | F16: 8.5 | G16: =F16 -> 8.5 | H16: =G16 -> 8.5 | I16: =H16 -> 8.5
A17: Vortrag: soziale Marktwirtschaft | B17: 45247 | C17: 0.5 | D17: 0.79166667 | E17: =D17-C17 -> 0.29166667 | F17: 7 | H17: =F17 -> 7 | I17: =H17 -> 7
A18: Heilsame Unterbrechung am Buß- und Bettag | B18: 45252 | C18: 0.33333333 | D18: 0.45833333 | E18: =D18-C18 -> 0.125 | F18: 3 | G18: =F18 -> 3
A19: Aufbau Zoomtechnik | B19: 45258 | C19: 0.39583333 | D19: 0.70833333 | E19: =D19-C19 -> 0.3125 | F19: 7.5 | G19: =F19 -> 7.5
A20: 75 Jahre Erklärung der Allgemeinen Menschenrechte | B20: 45259 | C20: 0.5 | D20: 0.91666667 | E20: =D20-C20 -> 0.41666667 | F20: 10 | G20: =F20 -> 10 | H20: =G20 -> 10 | I20: =H20 -> 10
A21: 75 Jahre Erklärung der Allgemeinen Menschenrechte | B21: 45260 | C21: 0.33333333 | D21: 0.58333333 | E21: =D21-C21 -> 0.25 | F21: 6 | G21: =F21 -> 6 | H21: =G21 -> 6 | I21: =H21 -> 6
A22: Fachkonferenz Migration und Behinderung | B22: 45274 | C22: 0.375 | D22: 0.75 | E22: =D22-C22 -> 0.375 | F22: 9 | G22: =F22 -> 9
A23: ENDSUMME | G23: =SUM(G3:G21) -> 153.25 | H23: =SUM(H3:H21) -> 129.25 | I23: =SUM(I3:I21) -> 129.25

Sheet EKD
A1: EKD VA | B1: Datum | C1: Startzeit | D1: Endzeit | E1: Differenz | F1: Umrech-nung | G1: Kirchsaal | H1: Georges-Casalis-Saal | I1: Entrée
A2: Frühgottesdienst | B2: 45000 | C2: 0.33333333 | D2: 0.375 | E2: =D2-C2 -> 0.041666667 | F2: 1 | G2: =F2 -> 1
A3: Entsendegottesdienst | B3: 45084 | C3: 0.33333333 | D3: 0.375 | E3: =D3-C3 -> 0.041666667 | F3: 1 | G3: =F3 -> 1
A4: Nachhaltigkeitskongress | B4: 45096 | C4: 0.375 | D4: 0.95833333 | E4: =D4-C4 -> 0.58333333 | F4: 14 | G4: =F4 -> 14 | H4: =G4 -> 14 | I4: =H4 -> 14
A5: Nachhaltigkeitskongress | B5: 45097 | C5: 0.33333333 | D5: 0.58333333 | E5: =D5-C5 -> 0.25 | F5: 6 | G5: =F5 -> 6 | H5: =G5 -> 6 | I5: =H5 -> 6
A6: Begehung BKA (Johannisempfang) | B6: 45091 | C6: 0.64583333 | D6: 0.70833333 | E6: =D6-C6 -> 0.0625 | F6: 1.5 | G6: =F6 -> 1.5 | H6: =G6 -> 1.5 | I6: =H6 -> 1.5
A7: Heilsame Unterbrechung am Buß- und Bettag | B7: 45252 | C7: 0.33333333 | D7: 0.45833333 | E7: =D7-C7 -> 0.125 | F7: 3 | G7: =F7 -> 3
A8: Johannisempfang | B8: 45098 | C8: 0.52083333 | D8: 0.97916667 | E8: =D8-C8 -> 0.45833333 | F8: 11 | G8: =F8 -> 11 | H8: =G8 -> 11 | I8: =H8 -> 11
A9: Adventssingen | B9: 45273 | C9: 0.75 | D9: 0.79166667 | E9: =D9-C9 -> 0.041666667 | F9: 1 | G9: =F9 -> 1
A10: Interne Andacht Bevollmächtigte | B10: 45278 | C10: 0.58333333 | D10: 0.60416667 | E10: =D10-C10 -> 0.020833333 | F10: 0.5 | G10: =F10 -> 0.5
A11: ENDSUMME | G11: =SUM(G4:G9) -> 36.5 | H11: =SUM(H4:H9) -> 32.5 | I11: =SUM(I4:I9) -> 32.5

Sheet Franz. Kirche 
I1: Französische Kirche
A2: Was | B2: Datum | C2: Startzeit | D2: Endzeit | E2: Differenz | F2: Umrech-nung | G2: Anzahl | H2: Kirchsaal | I2: Georges-Casalis-Saal | J2: Entrée
A3: Gottesdienst | B3: mehrere | C3: 0.41666667 | D3: 0.54166667 | E3: =D3-C3 -> 0.125 | F3: 3 | G3: 16 | H3: =G3*F3 -> 48
A4: Gottesdienst | B4: mehrere | C4: 0.4375 | D4: 0.5 | E4: =D4-C4 -> 0.0625 | F4: 1.5 | G4: 40 | H4: =G4*F4 -> 60
A5: Gottesdienst | B5: mehrere | C5: 0.45833333 | D5: 0.5 | E5: =D5-C5 -> 0.041666667 | F5: 1 | G5: 1 | H5: =G5*F5 -> 1
A6: Friedensgebet | B6: mehrere | C6: 0.5 | D6: 0.54166667 | E6: =D6-C6 -> 0.041666667 | F6: 1 | G6: 4 | H6: =G6*F6 -> 4
A7: culte | B7: mehrere | C7: 0.4375 | D7: 0.54166667 | E7: =D7-C7 -> 0.10416667 | F7: 2.5 | G7: 51 | I7: =(G7*F7) -> 127.5
A8: Mittagsandacht | B8: mehrere | C8: 0.5 | D8: 0.54166667 | E8: =D8-C8 -> 0.041666667 | F8: 1 | G8: 64 | H8: =F8*G8 -> 64
A9: Probe Choralschola | B9: 44935 | C9: 0.39583333 | D9: 0.5 | E9: =D9-C9 -> 0.10416667 | F9: 2.5 | G9: 1 | H9: =F9*G9 -> 2.5
A10: Probe Choralschola | B10: 44990 | C10: 0.41666667 | D10: 0.4375 | E10: =D10-C10 -> 0.020833333 | F10: 0.5 | G10: 1 | H10: =F10*G10 -> 0.5
A11: Aufnahmen Choralschola | B11: mehrere | C11: 0.35416667 | D11: 0.5 | E11: =D11-C11 -> 0.14583333 | F11: 3.5 | G11: 3 | H11: =F11*G11 -> 10.5
A12: Aufnahmen Choralschola | B12: mehrere | C12: 0.375 | D12: 0.5 | E12: =D12-C12 -> 0.125 | F12: 3 | G12: 3 | H12: =F12*G12 -> 9
A13: Probe & Orgelkonzert | B13: mehrere | C13: 0.33333333 | D13: 0.91666667 | E13: =D13-C13 -> 0.58333333 | F13: 14 | G13: 9 | H13: =F13*G13 -> 126
A14: Orgelkonzert intern | B14: 44982 | C14: 0.4375 | D14: 0.5 | E14: =D14-C14 -> 0.0625 | F14: 1.5 | G14: 1 | H14: =(G14*F14) -> 1.5
A15: Orgelkonzert | B15: 45048 | C15: 0.625 | D15: 0.70833333 | E15: =D15-C15 -> 0.083333333 | F15: 2 | G15: 1 | H15: =(G15*F15) -> 2
A16: Orgelkonzert | B16: 45291 | C16: 0.625 | D16: 0.70833333 | E16: =D16-C16 -> 0.083333333 | F16: 2 | G16: 1 | H16: =(G16*F16) -> 2
A17: Orgelstimmung | B17: 44990 | C17: 0.375 | D17: 0.41666667 | E17: =D17-C17 -> 0.041666667 | F17: 1 | G17: 1 | H17: =F17*G17 -> 1
A18: Orgelstimmung | B18: 45048 | C18: 0.54166667 | D18: 0.58333333 | E18: =D18-C18 -> 0.041666667 | F18: 1 | G18: 1 | H18: =F18*G18 -> 1
A19: Orgelstimmung | B19: 45264 | C19: 0.33333333 | D19: 0.375 | E19: =D19-C19 -> 0.041666667 | F19: 1 | G19: 1 | H19: =F19*G19 -> 1
A20: Orgelstimmung | B20: 45281 | C20: 0.58333333 | D20: 0.625 | E20: =D20-C20 -> 0.041666667 | F20: 1 | G20: 1 | H20: =F20*G20 -> 1
A21: Abnahme Orgel | B21: 44995 | C21: 0.375 | D21: 0.625 | E21: =D21-C21 -> 0.25 | F21: 6 | G21: 1 | H21: =F21*G21 -> 6
A22: Orgelarbeiten | B22: 44984 | C22: 0.33333333 | D22: 0.75 | E22: =D22-C22 -> 0.41666667 | F22: 10 | G22: 1 | H22: =F22*G22 -> 10
A23: Orgelarbeiten | B23: 44985 | C23: 0.33333333 | D23: 0.75 | E23: =D23-C23 -> 0.41666667 | F23: 10 | G23: 1 | H23: =F23*G23 -> 10
A24: Orgelarbeiten | B24: 44986 | C24: 0.33333333 | D24: 0.54166667 | E24: =D24-C24 -> 0.20833333 | F24: 5 | G24: 1 | H24: =F24*G24 -> 5
A25: Nacharbeiten Orgel | B25: 45084 | C25: 0.5625 | D25: 0.79166667 | E25: =D25-C25 -> 0.22916667 | F25: 5.5 | G25: 1 | H25: =F25*G25 -> 5.5
A26: Orgelmusik | B26: mehrere | C26: 0.625 | D26: 0.6875 | E26: =D26-C26 -> 0.0625 | F26: 1.5 | G26: 34 | H26: =G26*F26 -> 51
A27: Probe für Vesper | B27: mehrere | C27: 0.5 | D27: 0.625 | E27: =D27-C27 -> 0.125 | F27: 3 | G27: 6 | H27: =G27*F27 -> 18
A28: Probe für Konzert | B28: mehrere | C28: 0.54166667 | D28: 0.625 | E28: =D28-C28 -> 0.083333333 | F28: 2 | G28: 2 | H28: =G28*F28 -> 4
A29: Probe für Konzert | B29: mehrere | C29: 0.75 | D29: 0.91666667 | E29: =D29-C29 -> 0.16666667 | F29: 4 | G29: 7 | H29: =G29*F29 -> 28
A30: Probe für Konzert | B30: 45285 | C30: 0.54166667 | D30: 0.70833333 | E30: =D30-C30 -> 0.16666667 | F30: 4 | G30: 1 | H30: =G30*F30 -> 4
A31: Konzert zu Christi Sterbestunde | B31: 45023 | C31: 0.625 | D31: 0.70833333 | E31: =D31-C31 -> 0.083333333 | F31: 2 | G31: 1 | H31: =G31*F31 -> 2
A32: Garderobe Konzert | B32: 45023 | C32: 0.54166667 | D32: 0.70833333 | E32: =D32-C32 -> 0.16666667 | F32: 4 | G32: 1 | I32: =G32*F32 -> 4
A33: Chorprobe | B33: 45024 | C33: 0.45833333 | D33: 0.54166667 | E33: =D33-C33 -> 0.083333333 | F33: 2 | G33: 1 | H33: =G33*F33 -> 2
A34: Konzert am Ostermorgen | B34: 45025 | C34: 0.20833333 | D34: 0.3125 | E34: =D34-C34 -> 0.10416667 | F34: 2.5 | G34: 1 | H34: =G34*F34 -> 2.5
A35: Probe und musikalische Vesper | B35: 45075 | C35: 0.54166667 | D35: 0.75 | E35: =D35-C35 -> 0.20833333 | F35: 5 | G35: 1 | H35: =G35*F35 -> 5
A36: Musikalische Vesper | B36: mehrere | C36: 0.625 | D36: 0.75 | E36: =D36-C36 -> 0.125 | F36: 3 | G36: 6 | H36: =(G36*F36) -> 18
A37: Musikalischer Gottesdienst | B37: 45087 | C37: 0.625 | D37: 0.70833333 | E37: =D37-C37 -> 0.083333333 | F37: 2 | G37: 1 | H37: =(G37*F37) -> 2
A38: Musikalischer Gottesdienst | B38: 45115 | C38: 0.625 | D38: 0.75 | E38: =D38-C38 -> 0.125 | F38: 3 | G38: 1 | H38: =(G38*F38) -> 3
A39: Musikalischer Gottesdienst | B39: 45241 | C39: 0.58333333 | D39: 0.70833333 | E39: =D39-C39 -> 0.125 | F39: 3 | G39: 1 | H39: =(G39*F39) -> 3
A40: Musikalischer Gottesdienst | B40: mehrere | C40: 0.625 | D40: 0.72916667 | E40: =D40-C40 -> 0.10416667 | F40: 2.5 | G40: 4 | H40: =(G40*F40) -> 10
...

Sheet Orgelprobe
H1: Französische Kirche
A2: Was | B2: Datum | C2: Startzeit | D2: Endzeit | E2: Differenz | F2: Umrechnung | G2: Anzahl | H2: Kirchsaal | J2: Fertig
A3: Orgelprobe | B3: mehrere | C3: 0.375 | D3: 0.41666667 | E3: =D3-C3 -> 0.041666667 | F3: 1 | G3: 1 | H3: =(G3*F3) -> 1
A4: Orgelprobe | B4: mehrere | C4: 0.375 | D4: 0.4375 | E4: =D4-C4 -> 0.0625 | F4: 1 | G4: 1 | H4: =(G4*F4) -> 1
A5: Orgelprobe | B5: mehrere | C5: 0.375 | D5: 0.5 | E5: =D5-C5 -> 0.125 | F5: 3 | G5: 32 | H5: =G5*F5 -> 96
A6: Orgelprobe | B6: mehrere | C6: 0.375 | D6: 0.54166667 | E6: =D6-C6 -> 0.16666667 | F6: 4 | G6: 1 | H6: =G6*F6 -> 4
A7: Orgelprobe | B7: mehrere | C7: 0.41666667 | D7: 0.47916667 | E7: =D7-C7 -> 0.0625 | F7: 1.5 | G7: 1 | H7: =(G7*F7) -> 1.5
A8: Orgelprobe | B8: mehrere | C8: 0.41666667 | D8: 0.5 | E8: =D8-C8 -> 0.083333333 | F8: 2 | G8: 9 | H8: =(G8*F8) -> 18
A9: Orgelprobe | B9: mehrere | C9: 0.41666667 | D9: 0.52083333 | E9: =D9-C9 -> 0.10416667 | F9: 2.5 | H9: =(G9*F9) -> 0
A10: Orgelprobe | B10: mehrere | C10: 0.41666667 | D10: 0.54166667 | E10: =D10-C10 -> 0.125 | F10: 3 | G10: 3 | H10: =(G10*F10) -> 9
A11: Orgelprobe | B11: mehrere | C11: 0.41666667 | D11: 0.58333333 | E11: =D11-C11 -> 0.16666667 | F11: 4 | G11: 1 | H11: =(G11*F11) -> 4
A12: Orgelprobe | B12: mehrere | C12: 0.4375 | D12: 0.5 | E12: =D12-C12 -> 0.0625 | F12: 1.5 | H12: =(G12*F12) -> 0
A13: Orgelprobe | B13: mehrere | C13: 0.45833333 | D13: 0.5 | E13: =D13-C13 -> 0.041666667 | F13: 1 | H13: =(G13*F13) -> 0
A14: Orgelprobe | B14: mehrere | C14: 0.45833333 | D14: 0.52083333 | E14: =D14-C14 -> 0.0625 | F14: 1.5 | G14: 1 | H14: =(G14*F14) -> 1.5
A15: Orgelprobe | B15: mehrere | C15: 0.45833333 | D15: 0.54166667 | E15: =D15-C15 -> 0.083333333 | F15: 2 | G15: 2 | H15: =(G15*F15) -> 4
A16: Orgelprobe | B16: mehrere | C16: 0.45833333 | D16: 0.625 | E16: =D16-C16 -> 0.16666667 | F16: 4 | H16: =(G16*F16) -> 0
A17: Orgelprobe | B17: mehrere | C17: 0.47916667 | D17: 0.5 | E17: =D17-C17 -> 0.020833333 | F17: 0.5 | H17: =(G17*F17) -> 0
A18: Orgelprobe | B18: mehrere | C18: 0.5 | D18: 0.625 | E18: =D18-C18 -> 0.125 | F18: 3 | G18: 1 | H18: =(G18*F18) -> 3
A19: Orgelprobe | B19: mehrere | C19: 0.52083333 | D19: 0.66666667 | E19: =D19-C19 -> 0.14583333 | F19: 3.5 | H19: =(G19*F19) -> 0
A20: Orgelprobe | B20: mehrere | C20: 0.54166667 | D20: 0.625 | E20: =D20-C20 -> 0.083333333 | F20: 2 | G20: 2 | H20: =(G20*F20) -> 4
A21: Orgelprobe | B21: mehrere | C21: 0.54166667 | D21: 0.64583333 | E21: =D21-C21 -> 0.10416667 | F21: 2.5 | H21: =(G21*F21) -> 0
A22: Orgelprobe | B22: mehrere | C22: 0.54166667 | D22: 0.66666667 | E22: =D22-C22 -> 0.125 | F22: 3 | G22: 5 | H22: =(G22*F22) -> 15
A23: Orgelprobe | B23: mehrere | C23: 0.5625 | D23: 0.625 | E23: =D23-C23 -> 0.0625 | F23: 1.5 | G23: 1 | H23: =(G23*F23) -> 1.5
A24: Orgelprobe | B24: mehrere | C24: 0.5625 | D24: 0.64583333 | E24: =D24-C24 -> 0.083333333 | F24: 2 | G24: 1 | H24: =(G24*F24) -> 2
A25: Orgelprobe | B25: mehrere | C25: 0.5625 | D25: 0.66666667 | E25: =D25-C25 -> 0.10416667 | F25: 2.5 | G25: 6 | H25: =(G25*F25) -> 15
A26: Orgelprobe | B26: mehrere | C26: 0.5625 | D26: 0.6875 | E26: =D26-C26 -> 0.125 | F26: 3 | G26: 1 | H26: =(G26*F26) -> 3
A27: Orgelprobe | B27: mehrere | C27: 0.58333333 | D27: 0.625 | E27: =D27-C27 -> 0.041666667 | F27: 1 | G27: 2 | H27: =(G27*F27) -> 2
A28: Orgelprobe | B28: mehrere | C28: 0.58333333 | D28: 0.64583333 | E28: =D28-C28 -> 0.0625 | F28: 1.5 | G28: 1 | H28: =(G28*F28) -> 1.5
A29: Orgelprobe | B29: mehrere | C29: 0.58333333 | D29: 0.70833333 | E29: =D29-C29 -> 0.125 | F29: 3 | G29: 2 | H29: =(G29*F29) -> 6
A30: Orgelprobe | B30: mehrere | C30: 0.58333333 | D30: 0.75 | E30: =D30-C30 -> 0.16666667 | F30: 4 | G30: 1 | H30: =(G30*F30) -> 4
A31: Orgelprobe | B31: mehrere | C31: 0.625 | D31: 0.75 | E31: =D31-C31 -> 0.125 | F31: 3 | H31: =G31*F31 -> 0
A32: Orgelprobe | B32: mehrere | C32: 0.64583333 | D32: 0.70833333 | E32: =D32-C32 -> 0.0625 | F32: 1.5 | G32: 1 | H32: =G32*F32 -> 1.5
A33: Orgelprobe | B33: mehrere | C33: 0.66666667 | D33: 0.72916667 | E33: =D33-C33 -> 0.0625 | F33: 1.5 | G33: 1 | H33: =G33*F33 -> 1.5
A34: Orgelprobe | B34: mehrere | C34: 0.66666667 | D34: 0.75 | E34: =D34-C34 -> 0.083333333 | F34: 2 | G34: 1 | H34: =G34*F34 -> 2
A35: Orgelprobe | B35: mehrere | C35: 0.6875 | D35: 0.75 | E35: =D35-C35 -> 0.0625 | F35: 1.5 | G35: 1 | H35: =(G35*F35) -> 1.5
A36: Orgelprobe | B36: mehrere | C36: 0.6875 | D36: 0.79166667 | E36: =D36-C36 -> 0.10416667 | F36: 2.5 | G36: 1 | H36: =(G36*F36) -> 2.5
A37: Orgelprobe | B37: mehrere | C37: 0.70833333 | D37: 0.75 | E37: =D37-C37 -> 0.041666667 | F37: 1 | H37: =(G37*F37) -> 0
A38: Orgelprobe | B38: mehrere | C38: 0.70833333 | D38: 0.79166667 | E38: =D38-C38 -> 0.083333333 | F38: 2 | G38: 3 | H38: =(G38*F38) -> 6
A39: Orgelprobe | B39: mehrere | C39: 0.70833333 | D39: 0.83333333 | E39: =D39-C39 -> 0.125 | F39: 3 | G39: 1 | H39: =(G39*F39) -> 3
A40: Orgelprobe | B40: mehrere | C40: 0.70833333 | D40: 0.875 | E40: =D40-C40 -> 0.16666667 | F40: 4 | H40: =(G40*F40) -> 0
...

Sheet Offene Kirche
I1: Französische Kirche
A2: Was | B2: Datum Start | C2: Datum Ende | D2: Startzeit | E2: Endzeit | F2: Differenz | G2: Umrech-nung | H2: Anzahl | I2: Kirchsaal
A3: Offene Kirche | B3: viele | C3: viele | D3: 0.5 | E3: 0.54166667 | F3: =E3-D3 -> 0.041666667 | G3: 1 | H3: 29 | I3: =(H3*G3) -> 29
D4: 0.5 | E4: 0.58333333 | F4: 0.083333333 | G4: 2 | H4: 1 | I4: =(H4*G4) -> 2
A5: Offene Kirche | B5: viele | C5: viele | D5: 0.5 | E5: 0.60416667 | F5: =E5-D5 -> 0.10416667 | G5: 2.5 | H5: 6 | I5: =(H5*G5) -> 15
D6: 0.5 | E6: 0.625 | F6: 0.125 | G6: 3 | H6: 3 | I6: =G6*H6 -> 9
D7: 0.5 | E7: 0.64583333 | F7: 0.14583333 | G7: 3.5 | I7: =G7*H7 -> 0
D8: 0.5 | E8: 0.65625 | F8: 0.15625 | G8: 3.75 | I8: =G8*H8 -> 0
D9: 0.5 | E9: 0.66666667 | F9: 0.16666667 | G9: 4 | I9: =G9*H9 -> 0
D10: 0.5 | E10: 0.6875 | F10: 0.1875 | G10: 4.5 | I10: =G10*H10 -> 0
A11: Offene Kirche | B11: viele | C11: viele | D11: 0.5 | E11: 0.70833333 | F11: =E11-D11 -> 0.20833333 | G11: 5 | H11: 4 | I11: =(H11*G11) -> 20
D12: 0.5 | E12: 0.75 | F12: =E12-D12 -> 0.25 | G12: 6 | I12: =(H12*G12) -> 0
D13: 0.54166667 | E13: 0.58333333 | F13: =E13-D13 -> 0.041666667 | G13: 1 | I13: =H13*G13 -> 0
D14: 0.54166667 | E14: 0.60416667 | F14: 0.0625 | G14: 1.5 | I14: =H14*G14 -> 0
D15: 0.54166667 | E15: 0.625 | F15: 0.083333333 | G15: 2 | I15: =H15*G15 -> 0
D16: 0.54166667 | E16: 0.64583333 | F16: 0.10416667 | G16: 2.5 | I16: =G16*H16 -> 0
D17: 0.54166667 | E17: 0.66666667 | F17: 0.125 | G17: 3 | I17: =H17*G17 -> 0
A18: Offene Kirche | B18: viele | C18: viele | D18: 0.54166667 | E18: 0.70833333 | F18: =E18-D18 -> 0.16666667 | G18: 4 | I18: =(H18*G18) -> 0
A19: Offene Kirche | B19: viele | C19: viele | D19: 0.58333333 | E19: 0.70833333 | F19: =E19-D19 -> 0.125 | G19: 3 | I19: =(H19*G19) -> 0
D20: 0.60416667 | E20: 0.70833333 | F20: =E20-D20 -> 0.10416667 | G20: 2.5 | H20: 3 | I20: =(H20*G20) -> 7.5
D21: 0.625 | E21: 0.64583333 | F21: =E21-D21 -> 0.020833333 | G21: 0.5 | I21: =H21*G21 -> 0
A22: Offene Kirche | B22: viele | C22: viele | D22: 0.625 | E22: 0.70833333 | F22: =E22-D22 -> 0.083333333 | G22: 2 | H22: 3 | I22: =(H22*G22) -> 6
A23: Offene Kirche | B23: viele | C23: viele | D23: 0.625 | E23: 0.75 | F23: =E23-D23 -> 0.125 | G23: 3 | I23: =(H23*G23) -> 0
A24: Offene Kirche | B24: viele | C24: viele | G24: =SUM(G3:G23) -> 60.25 | H24: =SUM(H3:H23) -> 49 | I24: =SUM(I3:I23) -> 88.5
A26: ENDSUMME
A27: ENDSUMME
